<!-- Standalone MuJoCo XML updated from the v215 body for the current live GrowBot body, 2026-05-05. -->
<!-- Big measured geometry: body 132x83x39 mm; floor-to-body-bottom 44 mm; floor-to-servo-horn center 54 mm; legs 20 mm wide x 13.5 mm thick; IMU center 65 mm back from front at bottom shell. -->
<mujoco model="GrowBot_CurrentBody_20260505">
  <option gravity="0 0 -9.81" timestep="0.002000"/>
  <default>
    <geom solref="0.015 1" solimp="0.80 0.80 0.01" condim="3"/>
    <joint damping="0.040"/>
  </default>
  <worldbody>
    <geom name="floor" type="plane" size="2 2 0.1" rgba="0.88 0.92 0.88 1" friction="0.9500 0.1000 0.0500"/>
    <body name="base_body" pos="0 0 0.063500">
      <joint name="root_joint" type="free"/>
      <geom name="body_main" type="box" size="0.066000 0.041500 0.019500" pos="0 0 0" mass="0.070000" rgba="0.30 0.30 0.30 1"/>
      <geom name="servo_left" type="box" size="0.012 0.006 0.012" pos="-0.015000 -0.035500 -0.008500" mass="0.009000" rgba="0.18 0.18 0.18 1"/>
      <geom name="servo_right" type="box" size="0.012 0.006 0.012" pos="-0.015000 0.035500 -0.008500" mass="0.009000" rgba="0.18 0.18 0.18 1"/>
      <site name="imu_site" pos="0.001000 0 -0.019500" size="0.005"/>
      <site name="up_dir" pos="0 0 0.022" size="0.004"/>

      <body name="leg_left" pos="-0.015000 -0.041500 -0.008500">
        <joint name="joint_left" type="hinge" axis="0 1 0" limited="true" range="-90 90"/>
        <geom name="leg_left_geom" type="box" size="0.010000 0.006750 0.026000" pos="0 0 -0.026000" mass="0.012000" rgba="0.80 0.20 0.20 1"/>
        <geom name="left_foot_seg_0" type="box" size="0.000742 0.006500 0.003000" pos="-0.009800 0.000000 -0.050845" mass="0.000267" rgba="0.82 0.54 0.46 1" friction="1.0000 0.1000 0.0500"/>
        <geom name="left_foot_seg_1" type="box" size="0.000742 0.006500 0.003000" pos="-0.008400 0.000000 -0.051162" mass="0.000267" rgba="0.82 0.54 0.46 1" friction="1.0000 0.1000 0.0500"/>
        <geom name="left_foot_seg_2" type="box" size="0.000742 0.006500 0.003000" pos="-0.007000 0.000000 -0.051616" mass="0.000267" rgba="0.82 0.54 0.46 1" friction="1.0000 0.1000 0.0500"/>
        <geom name="left_foot_seg_3" type="box" size="0.000742 0.006500 0.003000" pos="-0.005600 0.000000 -0.051946" mass="0.000267" rgba="0.82 0.54 0.46 1" friction="1.0000 0.1000 0.0500"/>
        <geom name="left_foot_seg_4" type="box" size="0.000742 0.006500 0.003000" pos="-0.004200 0.000000 -0.052000" mass="0.000267" rgba="0.82 0.54 0.46 1" friction="1.0000 0.1000 0.0500"/>
        <geom name="left_foot_seg_5" type="box" size="0.000742 0.006500 0.003000" pos="-0.002800 0.000000 -0.052000" mass="0.000267" rgba="0.82 0.54 0.46 1" friction="1.0000 0.1000 0.0500"/>
        <geom name="left_foot_seg_6" type="box" size="0.000742 0.006500 0.003000" pos="-0.001400 0.000000 -0.052000" mass="0.000267" rgba="0.82 0.54 0.46 1" friction="1.0000 0.1000 0.0500"/>
        <geom name="left_foot_seg_7" type="box" size="0.000742 0.006500 0.003000" pos="0.000000 0.000000 -0.052000" mass="0.000267" rgba="0.82 0.54 0.46 1" friction="1.0000 0.1000 0.0500"/>
        <geom name="left_foot_seg_8" type="box" size="0.000742 0.006500 0.003000" pos="0.001400 0.000000 -0.052000" mass="0.000267" rgba="0.82 0.54 0.46 1" friction="1.0000 0.1000 0.0500"/>
        <geom name="left_foot_seg_9" type="box" size="0.000742 0.006500 0.003000" pos="0.002800 0.000000 -0.052000" mass="0.000267" rgba="0.82 0.54 0.46 1" friction="1.0000 0.1000 0.0500"/>
        <geom name="left_foot_seg_10" type="box" size="0.000742 0.006500 0.003000" pos="0.004200 0.000000 -0.052000" mass="0.000267" rgba="0.82 0.54 0.46 1" friction="1.0000 0.1000 0.0500"/>
        <geom name="left_foot_seg_11" type="box" size="0.000742 0.006500 0.003000" pos="0.005600 0.000000 -0.051946" mass="0.000267" rgba="0.82 0.54 0.46 1" friction="1.0000 0.1000 0.0500"/>
        <geom name="left_foot_seg_12" type="box" size="0.000742 0.006500 0.003000" pos="0.007000 0.000000 -0.051616" mass="0.000267" rgba="0.82 0.54 0.46 1" friction="1.0000 0.1000 0.0500"/>
        <geom name="left_foot_seg_13" type="box" size="0.000742 0.006500 0.003000" pos="0.008400 0.000000 -0.051162" mass="0.000267" rgba="0.82 0.54 0.46 1" friction="1.0000 0.1000 0.0500"/>
        <geom name="left_foot_seg_14" type="box" size="0.000742 0.006500 0.003000" pos="0.009800 0.000000 -0.050845" mass="0.000267" rgba="0.82 0.54 0.46 1" friction="1.0000 0.1000 0.0500"/>
      </body>

      <body name="leg_right" pos="-0.015000 0.041500 -0.008500">
        <joint name="joint_right" type="hinge" axis="0 1 0" limited="true" range="-90 90"/>
        <geom name="leg_right_geom" type="box" size="0.010000 0.006750 0.026000" pos="0 0 -0.026000" mass="0.012000" rgba="0.80 0.20 0.20 1"/>
        <geom name="right_foot_seg_0" type="box" size="0.000742 0.006500 0.003000" pos="-0.009800 0.000000 -0.050845" mass="0.000267" rgba="0.82 0.54 0.46 1" friction="1.0000 0.1000 0.0500"/>
        <geom name="right_foot_seg_1" type="box" size="0.000742 0.006500 0.003000" pos="-0.008400 0.000000 -0.051162" mass="0.000267" rgba="0.82 0.54 0.46 1" friction="1.0000 0.1000 0.0500"/>
        <geom name="right_foot_seg_2" type="box" size="0.000742 0.006500 0.003000" pos="-0.007000 0.000000 -0.051616" mass="0.000267" rgba="0.82 0.54 0.46 1" friction="1.0000 0.1000 0.0500"/>
        <geom name="right_foot_seg_3" type="box" size="0.000742 0.006500 0.003000" pos="-0.005600 0.000000 -0.051946" mass="0.000267" rgba="0.82 0.54 0.46 1" friction="1.0000 0.1000 0.0500"/>
        <geom name="right_foot_seg_4" type="box" size="0.000742 0.006500 0.003000" pos="-0.004200 0.000000 -0.052000" mass="0.000267" rgba="0.82 0.54 0.46 1" friction="1.0000 0.1000 0.0500"/>
        <geom name="right_foot_seg_5" type="box" size="0.000742 0.006500 0.003000" pos="-0.002800 0.000000 -0.052000" mass="0.000267" rgba="0.82 0.54 0.46 1" friction="1.0000 0.1000 0.0500"/>
        <geom name="right_foot_seg_6" type="box" size="0.000742 0.006500 0.003000" pos="-0.001400 0.000000 -0.052000" mass="0.000267" rgba="0.82 0.54 0.46 1" friction="1.0000 0.1000 0.0500"/>
        <geom name="right_foot_seg_7" type="box" size="0.000742 0.006500 0.003000" pos="0.000000 0.000000 -0.052000" mass="0.000267" rgba="0.82 0.54 0.46 1" friction="1.0000 0.1000 0.0500"/>
        <geom name="right_foot_seg_8" type="box" size="0.000742 0.006500 0.003000" pos="0.001400 0.000000 -0.052000" mass="0.000267" rgba="0.82 0.54 0.46 1" friction="1.0000 0.1000 0.0500"/>
        <geom name="right_foot_seg_9" type="box" size="0.000742 0.006500 0.003000" pos="0.002800 0.000000 -0.052000" mass="0.000267" rgba="0.82 0.54 0.46 1" friction="1.0000 0.1000 0.0500"/>
        <geom name="right_foot_seg_10" type="box" size="0.000742 0.006500 0.003000" pos="0.004200 0.000000 -0.052000" mass="0.000267" rgba="0.82 0.54 0.46 1" friction="1.0000 0.1000 0.0500"/>
        <geom name="right_foot_seg_11" type="box" size="0.000742 0.006500 0.003000" pos="0.005600 0.000000 -0.051946" mass="0.000267" rgba="0.82 0.54 0.46 1" friction="1.0000 0.1000 0.0500"/>
        <geom name="right_foot_seg_12" type="box" size="0.000742 0.006500 0.003000" pos="0.007000 0.000000 -0.051616" mass="0.000267" rgba="0.82 0.54 0.46 1" friction="1.0000 0.1000 0.0500"/>
        <geom name="right_foot_seg_13" type="box" size="0.000742 0.006500 0.003000" pos="0.008400 0.000000 -0.051162" mass="0.000267" rgba="0.82 0.54 0.46 1" friction="1.0000 0.1000 0.0500"/>
        <geom name="right_foot_seg_14" type="box" size="0.000742 0.006500 0.003000" pos="0.009800 0.000000 -0.050845" mass="0.000267" rgba="0.82 0.54 0.46 1" friction="1.0000 0.1000 0.0500"/>
      </body>
    </body>
  </worldbody>
  <sensor>
    <accelerometer name="acc" site="imu_site" noise="0.03" cutoff="30"/>
    <gyro name="gyro" site="imu_site" noise="0.01" cutoff="30"/>
  </sensor>
  <actuator>
    <position name="servo_left" joint="joint_left" kp="0.8500"/>
    <position name="servo_right" joint="joint_right" kp="0.8500"/>
  </actuator>
</mujoco>
